Workbook

Sheet 1. Overview
A1: Manila Trip Overview — 2026-05-28 → 2026-06-01
A3: Trip dates | B3: 2026-05-28 → 2026-06-01
A4: Nights / Days | B4: 4 nights
A5: Origin | B5: Domestic / Provincial Philippines — Philippine Airlines / Cebu Pacific (domestic)
A6: Destination | B6: Manila
A7: Outbound flight | B7: Thu 28 May — arrival NAIA (domestic terminal)
A8: Return flight | B8: Mon 01 Jun — depart NAIA
A9: Passport | B9: Philippines
A10: Visa | B10: Domestic travel — no visa. PH passport / any valid government-issued photo ID required for domestic flights.
A11: Base hotel | B11: Makati CBD (Ayala / Poblacion side)
A12: Travelers | B12: 1 pax
A13: Currency | B13: PHP ~43 per 1 SGD
A14: Climate | B14: Hot late dry → habagat onset, 28-34°C, humidity 75-90%, afternoon thunderstorms possible by end May/early Jun
... A18: Emergency | B18: Police/Fire/Ambulance 911 (national) · NAIA Tourist Police: +63 2 8551 9888
A20: ⚠️ Risk Flags & Mitigations
A22: Habagat onset | B22: Late May / early Jun = start of SW monsoon. Afternoon thunderstorms 30-40% days. Pack rain shell + dry-bag for electronics.
A23: NAIA traffic | B23: EDSA + Skyway worst 16:30-20:00 Mon-Fri. Allow 60-75min Makati→NAIA Mon 01 Jun PM departure.
A24: Tagaytay traffic Sat | B24: Tagaytay weekend traffic adds 30-60min each way. Leave Makati by 07:00 OR delay to Mon (skip flight day).
A25: Quiapo pickpockets | B25: Plaza Miranda crowded — wear money belt, no flashy phone, leave passport at hotel.
A26: Day 2 fatigue (v1) | B26: Binondo food crawl + Quiapo + Escolta + Poblacion crawl = high; v2 cuts Quiapo + crawl optional.
A27: Pinatubo flood risk | B27: Early-season tropical depressions possible; monitor PAGASA for LPA 1 week pre-trip.
A28: Taal volcano alert | B28: Day-trip to Tagaytay rim viewpoint OK at Alert Level 1-2; crater boat ride NOT allowed >Level 2. Check PHIVOLCS.
A29: NAIA terminal mix-up | B29: PH airlines split T2/T3/T4. PAL=T2, Cebu Pacific=T3 (intl/domestic mixed). Confirm terminal on booking — wrong terminal = miss flight.
A30: Currency cash | B30: Many small eateries + jeepneys cash-only. GCash accepted in Makati/BGC but spotty in Binondo/Quiapo. Carry ₱2-3k cash daily.
A31: Pollution/heat | B31: Heat index can hit 42°C midday late May. Indoor break 12:00-15:00; hydrate.
A33: 📌 Three itinerary variants — adjacent tabs: Sheet 3 (v1 standard) · Sheet 4 (v2 relaxed) · Sheet 5 (v3 bad-weather) · Sheet 6 (v1 vs v2 compare)

Sheet 2. Booking Timeline
A1: 📅 Booking Strategy Timeline (relative to 2026-05-28)
A3: Window | B3: Lead time | C3: Action | D3: Why
A4: Now → Feb 2026 | B4: T-3 to T-5 mo | C4: Track domestic fare via Cebu Pacific / PAL apps; set price alerts | D4: Domestic fare swings ±50%; promos around payday Fridays
A5: Feb 2026 | B5: T-3 mo | C5: Book Cebu Pacific / PAL return; target Tue/Wed flights | D5: Mid-week cheaper; avoid Friday return = NAIA chaos
A6: Mar 2026 | B6: T-2 mo | C6: Book hotel on Agoda/Booking with FREE CANCELLATION (Makati CBD) | D6: Lock rate; pivot if flash sale or pivot to BGC
A7: Apr 2026 | B7: T-1 mo | C7: Pre-book Tagaytay private car / Klook tour; book Toyo Eatery 2 weeks ahead | D7: Tagaytay weekend slots fill; Toyo books out
A8: Early May 2026 | B8: T-3 wk | C8: Book Corregidor (Sun Cruises) if pivoting from Tagaytay | D8: Sun Cruises only ferry — limited Sat slots
A9: 2 weeks before | B9: T-2 wk | C9: Reconfirm Toyo Eatery + Old Manila Walks Binondo crawl | D9: Both small operators with limited covers
A10: 1 week before | B10: T-7 d | C10: WhatsApp The Spa BGC / Nuat Thai for Sat/Sun reservation | D10: Weekend spa slots fill
A11: 3 days before | B11: T-3 d | C11: Web check-in opens — confirm seats; verify terminal (T2/T3) | D11: Avoid airport counter queue + terminal mix-up
A12: Day before | B12: T-1 d | C12: Screenshot all vouchers offline; charge devices; download PAGASA app | D12: Mobile data patchy at NAIA arrival
A13: Day of | B13: T-0 | C13: Domestic: arrive NAIA T-1.5hr; check terminal once more | D13: Domestic shorter buffer but terminal errors common

Sheet 3. v1 Daily Itinerary
A1: 🗺️ v1 Standard Pace Itinerary
A3: Day 1 — Thu 28 May: Arrival + Intramuros + Bay Sunset
A4: Time | B4: Activity | C4: From -> To | D4: Dist (km) | E4: Travel (min) | F4: Cost (local) | G4: Cost (SGD) | H4: Notes | I4: ✓
A5: AM | B5: Arrive NAIA (domestic terminal — T2/T3/T4 depending on carrier) | C5: NAIA arrival | F5: 0 | H5: Domestic — show valid government ID | I5: ☐
A6: +45m | B6: Grab to Makati hotel; check in or store bags | C6: NAIA → Makati | D6: 8.5 | E6: 35 | F6: 350 | H6: EDSA traffic — allow 30-50min | I6: ☐
A7: 11:30 | B7: Light lunch near hotel (Manam Greenbelt or Mesa) | C7: Walk Ayala/Greenbelt | D7: 0.6 | E7: 8 | F7: 500 | I7: ☐
A8: 13:00 | B8: Grab to Intramuros — start at Fort Santiago | C8: Makati → Intramuros | D8: 7.5 | E8: 30 | F8: 280 | H8: Entry ₱75 | I8: ☐
A9: 14:00 | B9: Fort Santiago + Rizal Shrine walk | C9: Within Intramuros | E9: 60 | F9: 75 | H9: Allow 1hr | I9: ☐
A10: 15:00 | B10: San Agustin Church + Museum | C10: Walk | D10: 0.4 | E10: 8 | F10: 200 | H10: UNESCO; AC inside | I10: ☐
A11: 16:00 | B11: Casa Manila + Manila Cathedral | C11: Walk | D11: 0.3 | E11: 6 | F11: 75 | I11: ☐
A12: 17:15 | B12: Grab to Manila Baywalk | C12: Intramuros → Baywalk | D12: 2 | E12: 12 | F12: 150 | H12: For sunset | I12: ☐
A13: 17:30 | B13: Manila Bay sunset | C13: Roxas Blvd walk | E13: 60 | F13: 0 | H13: Free | I13: ☐
A14: 19:00 | B14: Dinner: Aristocrat Roxas Blvd | C14: Walk Roxas Blvd | D14: 0.5 | E14: 8 | F14: 600 | H14: Chicken BBQ classic | I14: ☐
A15: 21:00 | B15: Grab back to Makati | C15: Malate → Makati | D15: 6 | E15: 25 | F15: 280 | I15: ☐
A16: Day total | D16: =SUM(D5:D15) | E16: =SUM(E5:E15) | F16: =SUM(F5:F15) | G16: =SUM(G5:G15)
A18: Day 2 — Fri 29 May: Binondo Food Crawl + Quiapo + Escolta
A19: Time | B19: Activity | C19: From -> To | D19: Dist (km) | E19: Travel (min) | F19: Cost (local) | G19: Cost (SGD) | H19: Notes | I19: ✓
A20: 08:30 | B20: Quick hotel breakfast | C20: Hotel | F20: 0 | I20: ☐
A21: 09:30 | B21: Grab to Binondo (Plaza Lorenzo Ruiz) | C21: Makati → Binondo | D21: 8.2 | E21: 30 | F21: 320 | I21: ☐
A22: 10:00 | B22: Old Manila Walks Big Binondo Food Wok | C22: Binondo walk | E22: 240 | F22: 1500 | H22: Book ahead; eats included | I22: ☐
A23: 14:00 | B23: Cross Jones Bridge to Quiapo | C23: Walk over Pasig | D23: 1 | E23: 18 | F23: 0 | I23: ☐
A24: 14:30 | B24: Quiapo Church + Plaza Miranda | C24: Within Quiapo | E24: 45 | F24: 0 | H24: Watch belongings | I24: ☐
A25: 15:30 | B25: Hidalgo St photography row + Villalobos herb stalls | C25: Quiapo streets | E25: 45 | F25: 0 | I25: ☐
A26: 16:30 | B26: Grab to Escolta — heritage art district | C26: Quiapo → Escolta | D26: 1 | E26: 10 | F26: 100 | I26: ☐
A27: 17:00 | B27: Calvo Building, HUB:Make Lab, Capitol Theatre ruins | C27: Walk Escolta | E27: 60 | F27: 0 | I27: ☐
A28: 18:30 | B28: Grab back to Makati — rest 1hr | C28: Escolta → Makati | D28: 8.5 | E28: 35 | F28: 350 | H28: Rush hour buffer | I28: ☐
A29: 20:30 | B29: Dinner: Manam Greenbelt | C29: Walk Ayala | D29: 0.5 | E29: 8 | F29: 700 | I29: ☐
A30: 22:00 | B30: Z Hostel Rooftop / Poblacion bar crawl | C30: Walk Poblacion | D30: 0.6 | E30: 10 | F30: 600 | H30: Optional | I30: ☐
A31: Day total | D31: =SUM(D20:D30) | E31: =SUM(E20:E30) | F31: =SUM(F20:F30) | G31: =SUM(G20:G30)
A33: Day 3 — Sat 30 May: Tagaytay Day Trip (Taal + Bulalo)
A34: Time | B34: Activity | C34: From -> To | D34: Dist (km) | E34: Travel (min) | F34: Cost (local) | G34: Cost (SGD) | H34: Notes | I34: ✓
A35: 07:00 | B35: Hotel pickup — private car or Grab to Tagaytay | C35: Makati → Tagaytay | D35: 60 | E35: 105 | F35: 3500 | H35: Private car ₱3,500-4,500 RT | I35: ☐
A36: 09:00 | B36: Picnic Grove / People's Park in the Sky — Taal panorama | C36: Tagaytay ridge | E36: 90 | F36: 100 | H36: Cool 22-25°C | I36: ☐
A37: 11:00 | B37: Sky Ranch (optional ferris wheel) | C37: Tagaytay | E37: 60 | F37: 600 | H37: Skip if not into rides | I37: ☐
A38: 12:30 | B38: Lunch: Bulalo at Leslie's / Diner's | C38: Aguinaldo Hwy | E38: 75 | F38: 750 | H38: Bone-marrow beef stew | I38: ☐
A39: 14:30 | B39: Sonya's Garden — organic farm + cafe | C39: Alfonso side | D39: 8 | E39: 20 | F39: 250 | H39: Pretty stop | I39: ☐
A40: 16:00 | B40: Mahogany Market for souvenirs (kapeng barako, buko pie) | C40: Tagaytay | E40: 45 | F40: 400 | I40: ☐
A41: 17:00 | B41: Drive back to Makati | C41: Tagaytay → Makati | D41: 60 | E41: 120 | F41: 0 | H41: Light Sat traffic outbound | I41: ☐
A42: 19:30 | B42: Massage: Nuat Thai or The Spa BGC | C42: Hotel area | D42: 1 | E42: 10 | F42: 700 | H42: Recover from drive | I42: ☐
A43: 21:30 | B43: Late dinner near hotel or skip | C43: Walk | F43: 500 | I43: ☐
...

Sheet 4. v2 Relaxed Pace
A1: 🛋️ Relaxed Pace v2 — Less-Touristy
A3: Day 1 — Thu 28 May: Soft Arrival + Sunset
A4: Time | B4: Activity | C4: From -> To | D4: Dist (km) | E4: Travel (min) | F4: Cost (local) | G4: Cost (SGD) | H4: Notes | I4: ✓
A5: AM | B5: Arrive NAIA + Grab to Makati | C5: NAIA → Makati | D5: 8.5 | E5: 35 | F5: 350 | I5: ☐
A6: 12:00 | B6: Lazy lunch near hotel — Manam or Mesa | C6: Walk | F6: 500 | I6: ☐
A7: 13:30 | B7: Hotel pool / nap block | C7: Hotel | E7: 150 | F7: 0 | H7: Decompress | I7: ☐
A8: 16:30 | B8: Grab to Manila Baywalk for sunset only | C8: Makati → Baywalk | D8: 6.5 | E8: 25 | F8: 280 | H8: Skip Intramuros today | I8: ☐
A9: 19:00 | B9: Dinner: Café Adriatico Malate (heritage) | C9: Walk Malate | D9: 0.6 | E9: 10 | F9: 700 | I9: ☐
A10: 21:00 | B10: Grab back; early night | C10: Malate → Makati | D10: 6 | E10: 25 | F10: 280 | I10: ☐
A11: Day total | D11: =SUM(D5:D10) | E11: =SUM(E5:E10) | F11: =SUM(F5:F10) | G11: =SUM(G5:G10)
A13: Day 2 — Fri 29 May: Sunrise Intramuros + Slow Binondo
A14: Time | B14: Activity | C14: From -> To | D14: Dist (km) | E14: Travel (min) | F14: Cost (local) | G14: Cost (SGD) | H14: Notes | I14: ✓
A15: 05:30 | B15: Grab to Intramuros — empty walls at sunrise | C15: Makati → Intramuros | D15: 7.5 | E15: 18 | F15: 250 | H15: No traffic; cool | I15: ☐
A16: 06:00 | B16: Walk walls + Fort Santiago perimeter (opens 08:00 — exterior only earlier) | C16: Intramuros | E16: 90 | F16: 0 | I16: ☐
A17: 08:00 | B17: Fort Santiago + San Agustin | C17: Intramuros | E17: 120 | F17: 275 | I17: ☐
A18: 10:30 | B18: Coffee + breakfast at Barbara's Heritage | C18: Intramuros | F18: 450 | H18: Quiet AC break | I18: ☐
A19: 12:00 | B19: Walk to Binondo via Jones Bridge | C19: Walk | D19: 2 | E19: 25 | F19: 0 | H19: Skip Quiapo crowds in v2 | I19: ☐
A20: 12:30 | B20: Slow Binondo — self-paced (Wai Ying + Eng Bee Tin) | C20: Binondo walk | E20: 120 | F20: 700 | H20: Skip the group tour | I20: ☐
A21: 15:00 | B21: Grab back to Makati — rest block | C21: Binondo → Makati | D21: 8 | E21: 35 | F21: 350 | I21: ☐
A22: 16:30 | B22: Nuat Thai foot reflex 60min | C22: Walk | E22: 60 | F22: 500 | I22: ☐
A23: 19:30 | B23: Dinner: Sentro 1771 (Greenbelt) | C23: Walk | F23: 800 | I23: ☐
A24: 21:30 | B24: Optional nightcap — skip if tired | F24: 0 | I24: ☐
A25: Day total | D25: =SUM(D15:D24) | E25: =SUM(E15:E24) | F25: =SUM(F15:F24) | G25: =SUM(G15:G24)
A27: Day 3 — Sat 30 May: Antipolo Art + Quiet Lunch (skip Tagaytay crowds)
A28: Time | B28: Activity | C28: From -> To | D28: Dist (km) | E28: Travel (min) | F28: Cost (local) | G28: Cost (SGD) | H28: Notes | I28: ✓
A29: 09:00 | B29: Late breakfast at hotel | C29: Hotel | F29: 0 | I29: ☐
A30: 10:30 | B30: Grab to Pinto Art Museum (Antipolo) | C30: Makati → Antipolo | D30: 28 | E30: 75 | F30: 850 | H30: Less crowded than Tagaytay | I30: ☐
A31: 12:00 | B31: Pinto galleries + gardens + cafe lunch | C31: Within Pinto | E31: 180 | F31: 1200 | H31: Entry ₱250 + lunch | I31: ☐
A32: 15:30 | B32: Grab back to Makati | C32: Antipolo → Makati | D32: 28 | E32: 75 | F32: 850 | I32: ☐
A33: 17:00 | B33: Hotel rest / pool | C33: Hotel | E33: 90 | F33: 0 | I33: ☐
A34: 19:00 | B34: Long ritual at The Spa BGC — 150min | C34: BGC | D34: 4 | E34: 18 | F34: 3200 | H34: Single long session | I34: ☐
A35: 22:00 | B35: Light supper near hotel | C35: Walk | F35: 500 | I35: ☐
A36: Day total | D36: =SUM(D29:D35) | E36: =SUM(E29:E35) | F36: =SUM(F29:F35) | G36: =SUM(G29:G35)
A38: Day 4 — Sun 31 May: Slow Makati + Optional BGC
A39: Time | B39: Activity | C39: From -> To | D39: Dist (km) | E39: Travel (min) | F39: Cost (local) | G39: Cost (SGD) | H39: Notes | I39: ✓
A40: 09:00 | B40: Legaspi Market wander | C40: Walk | E40: 75 | F40: 500 | I40: ☐
A41: 10:30 | B41: Ayala Museum (no rush — 2.5hr) | C41: Walk | E41: 150 | F41: 650 | I41: ☐
A42: 13:30 | B42: Long lunch: Toyo Eatery (book ahead) or Wildflour | C42: Karrivin/Makati | E42: 150 | F42: 3000 | I42: ☐
A43: 16:30 | B43: Hotel pool / book / nap | C43: Hotel | E43: 120 | F43: 0 | I43: ☐
A44: 19:00 | B44: BGC stroll — optional gallery / High Street | C44: BGC | D44: 4 | E44: 18 | F44: 200 | H44: Skip if tired | I44: ☐
...

Sheet 5. v3 Bad Weather Plan B
A1: 🌧️ Bad Weather Plan B (v3) — Indoor / Sheltered Swaps
A2: Late May–early June = transition from amihan (dry/cool) to habagat (SW monsoon). Manila prone to sudden afternoon thunderstorms + occasional early tropical depressions. Heat index can exceed 42°C midday. Indoor fallbacks mandatory.
A4: 🌦️ Morning Forecast Decision Tree
A5: Condition | B5: Trigger | C5: Action
A6: Clear / partly cloudy (heat index <38°C) | B6: PAGASA forecast clear | C6: Run v1 standard
A7: PM afternoon showers (typical habagat) | B7: Showers forecast 13:00-17:00 | C7: Front-load outdoor AM, shift indoor museum/mall PM
A8: All-day moderate rain | B8: Yellow rainfall warning | C8: Activate v3 — indoor chain, skip Tagaytay/Corregidor
A9: Tropical storm / Signal No.1-2 | B9: PAGASA TCWS-1/2 | C9: Cancel all day-trips; stay Makati; cinema/spa/mall
A10: Typhoon / Signal No.3+ | B10: PAGASA TCWS-3+ | C10: Stay in hotel; assume flight cancellation; extend booking; insurance claim
A12: 🔄 Per-Day Bad-Weather Swaps
A13: Day 1 — Thu 28 May
A14: Original item | B14: Why at risk | C14: Trigger | D14: Plan-B action | E14: Alt PHP | F14: Channel
A15: Intramuros walking (PM) | B15: Open cobblestone, no cover except churches | C15: Any rain | D15: Skip outdoor; do Casa Manila + San Agustin Museum (covered) only, OR move to Day 2 sunrise. | E15: 275 | F15: Self-walk
A16: Manila Baywalk sunset | B16: Fully open seafront | C16: Mod rain | D16: Substitute Sky Deck Bayleaf (covered rooftop, Intramuros views) OR hotel rooftop bar. | E16: 600 | F16: Bayleaf Hotel walk-in
A17: Aristocrat dinner | B17: Indoor — OK in light rain | C17: Heavy rain | D17: Stay Makati: Romulo Café / Manam Greenbelt (covered access). | E17: 700 | F17: Walk via covered walkway
A19: Day 2 — Fri 29 May
A20: Original item | B20: Why at risk | C20: Trigger | D20: Plan-B action | E20: Alt PHP | F20: Channel
A21: Binondo food crawl (walking) | B21: Outdoor walking between stalls | C21: Mod rain | D21: Crawl uses covered shophouses — proceed with umbrella. Skip Quiapo (open plaza). | E21: 1500 | F21: Old Manila Walks
A22: Quiapo Church + Hidalgo St | B22: Open plaza + flooded streets | C22: Mod-Heavy rain | D22: SKIP — Quiapo floods at 30mm+ rain. Substitute Bahay Tsinoy (Intramuros) AC museum. | E22: 200 | F22: Self-walk
A23: Escolta heritage walk | B23: Outdoor street walk | C23: Heavy rain | D23: Lucky Chinatown Mall (covered) for refuge; reschedule Escolta to Day 4. | F23: Mall
A24: Poblacion crawl | B24: Walking between bars | C24: Any rain | D24: Pick ONE indoor bar (The Curator speakeasy, Bank Bar) instead of crawl. | E24: 600 | F24: Reservation
A26: Day 3 — Sat 30 May
A27: Original item | B27: Why at risk | C27: Trigger | D27: Plan-B action | E27: Alt PHP | F27: Channel
A28: Tagaytay day trip | B28: Long mountain drive + outdoor viewpoints; Taal lake view = ZERO in rain | C28: Mod rain or worse | D28: CANCEL Tagaytay. SUBSTITUTE: Pinto Art Museum (Antipolo, mostly covered) OR full-day mall+museum chain. | E28: 250 | F28: Klook refund if 24hr
A29: Tagaytay (storm) | B29: Aguinaldo Hwy lands floods + visibility nil | C29: Tropical storm signal 1+ | D29: STAY MAKATI. National Museum complex (FREE, AC, 3-4hr) + spa marathon. | F29: Walk-in
A30: Taal volcano boat | B30: Open lake | C30: Wind >40km/h OR PHIVOLCS Alert 2+ | D30: CANCEL — boat ops suspended. Refund via operator. | F30: Operator refund
A32: Day 4 — Sun 31 May
A33: Original item | B33: Why at risk | C33: Trigger | D33: Plan-B action | E33: Alt PHP | F33: Channel
A34: Legaspi Sunday Market | B34: Outdoor market | C34: Any rain | D34: Market runs in light rain (tarps); heavy rain — vendors close. Substitute: hotel breakfast + Wildflour Salcedo. | E34: 400 | F34: Walk-in
A35: Ayala Museum | B35: Fully indoor AC | C35: Any | D35: ALREADY INDOOR ✅ — keep as primary. Extend to 3hr if rain continues. | E35: 650 | F35: Walk-in
A36: BGC street art walk | B36: Outdoor walking | C36: Mod rain | D36: SKIP. Substitute: Mind Museum BGC (indoor, ₱750, 2hr) + Bonifacio High Street covered walkways. | E36: 750 | F36: Walk-in
A37: Toyo Eatery dinner (booked) | B37: Indoor restaurant | C37: Any | D37: ALREADY INDOOR ✅ — Grab to Karrivin. Allow extra time for traffic. | E37: 3500 | F37: Reservation
A39: Day 5 — Mon 01 Jun
A40: Original item | B40: Why at risk | C40: Trigger | D40: Plan-B action | E40: Alt PHP | F40: Channel
A41: Pasalubong run + final lunch | B41: Mostly indoor malls | C41: Any | D41: ✅ Already indoor — Greenbelt + SM Aura. Skip outdoor stops. | E41: 1500 | F41: Mall
A42: Grab to NAIA | B42: EDSA floods + traffic doubles | C42: Heavy rain | D42: Leave Makati 3hr before flight (vs 2hr). Use Skyway not EDSA. Have Grab Plus / 6-seater backup. | E42: 600 | F42: Grab
A43: Flight departure | B43: Domestic flights cancel at PAGASA Signal 2+ near track | C43: Typhoon signal 2+ | D43: Cebu Pacific / PAL waive rebook fee during published advisories. Check carrier app + Twitter. Extend hotel free-cancel rate if delayed. | F43: Carrier app
A46: 🏠 Indoor Activity Bank
A47: Activity | B47: Area | C47: PHP | D47: Duration | E47: Notes
A48: Ayala Museum | B48: Makati | C48: 650 | D48: 2.5-3hr | E48: Gold gallery + Diorama
...

Sheet 6. v1 vs v2 Compare
A1: ⚖️ v1 Standard vs v2 Relaxed Less-Touristy
A3: Item | B3: v1 — Standard | C3: v2 — Relaxed Less-Touristy | D3: Why change
A4: Day 1 PM | B4: Intramuros half-day + Manila Bay sunset (active) | C4: Hotel pool + Baywalk sunset only | D4: Soft arrival; avoid heat exhaustion day 1
A5: Day 2 | B5: Binondo crawl + Quiapo + Escolta + Poblacion nightlife | C5: Sunrise Intramuros + slow Binondo (skip Quiapo) | D5: v1 too packed — 4 walking-heavy stops + late bars
A6: Day 3 anchor | B6: Tagaytay day trip (60km RT, peak weekend crowds) | C6: Pinto Art Museum Antipolo (28km, quiet curated art) | D6: v2 cuts long drive + skips Tagaytay weekend traffic
A7: Day 4 | B7: Ayala Museum + BGC + spa + Toyo Eatery dinner + nightcap | C7: Legaspi Market + Ayala Museum + long Toyo lunch + rest | D7: v1 = 13hr active; v2 = 9hr + nap block
A8: Day 5 departure | B8: Pasalubong + lunch + Grab NAIA T-2hr | C8: Easy breakfast + light shopping + Grab NAIA T-3hr | D8: Habagat = NAIA delays; extra buffer
A9: Total spa time | B9: 60 + 90 = 150min two sessions | C9: 150min single long ritual | D9: Quality > quantity
A10: Avg daily transit km | B10: ~28 km | C10: ~22 km | D10: v2 trades Tagaytay for shorter Antipolo + sunrise Intramuros (less traffic)
A11: Crowd exposure | B11: High (Binondo crawl + Quiapo + Tagaytay weekend) | C11: Low (sunrise Intramuros + Antipolo art + Legaspi local) | D11: v2 avoids tour-bus + religious-crowd zones
A12: Heat exposure | B12: High (3 outdoor anchors) | C12: Medium (sunrise + indoor museum + spa) | D12: v2 keeps 11-15:00 indoor
A13: Nightlife | B13: Mandatory Poblacion crawl + The Curator nightcap | C13: Optional — only if energy permits | D13: Free weather/energy pivot
A14: Active hours/day | B14: 13-14 hr | C14: 10-12 hr with 2× rest blocks | D14: Pace for couples/leisure/heat tolerance

Sheet 7. Accommodation
A1: 🏨 Accommodation Options — Makati CBD (Ayala / Poblacion side)
A3: Hotel | B3: Tier | C3: Rating | D3: SGD/night (low) | E3: SGD/night (high) | F3: Notes
A4: Red Planet Makati (Mabini) | B4: Budget | C4: 3★ | D4: 35 | E4: 55 | F4: Walking distance Poblacion + Greenbelt. Clean, no-frills. Best budget pick.
A5: Citadines Salcedo Makati | B5: Mid | C5: 4★ | D5: 90 | E5: 140 | F5: Aparthotel with kitchen, gym, pool. Salcedo Village near Saturday market. Mid-range sweet spot.
A6: Dusit Thani Manila | B6: Luxury | C6: 5★ | D6: 200 | E6: 320 | F6: Across Ayala MRT, walking to Greenbelt/Ayala Museum. Devarana Spa onsite. Reliable luxury.
A7: Shangri-La The Fort (BGC) | B7: Luxury | C7: 5★ | D7: 280 | E7: 450 | F7: If staying BGC instead of Makati. Tallest hotel in PH. Samba rooftop bar, CHI Spa.
A9: RECOMMENDATION: Single hotel in Makati CBD (walking distance to Greenbelt + Poblacion + Salcedo). Citadines Salcedo = sweet spot mid-range. Book Free Cancellation rate to allow late pivot to BGC if needed. Avoid Manila/Ermita budget hotels (further from BGC, worse safety after dark).

Sheet 8. Food, Spas, Nightlife
A1: 🍜 Food / 💆 Spa / 🍻 Nightlife
A3: 🍜 Food — Must-Try
A4: Place | B4: Area | C4: Price (PHP) | D4: Notes | E4: When
A5: Wai Ying Fastfood | B5: Binondo | C5: ₱200-350 | D5: Cheap, fast Cantonese dimsum + hakaw + soy chicken. Cult favorite. Two branches (Benavidez + Salazar). Cash only. | E5: Day 2 Binondo crawl lunch
A6: Manam Comfort Filipino | B6: Greenbelt 2, Makati | C6: ₱400-700 | D6: Modern Filipino tapas — sinigang sa watermelon, crispy pata, kare-kare. Order classics + twist sides. Walk-ins okay weekday lunch. | E6: Day 1 lunch / Day 2 dinner
A7: Toyo Eatery | B7: Karrivin Plaza, Makati | C7: ₱3,500-4,500 tasting | D7: Asia's 50 Best — pinakbet bukid, Filipino tasting menu. Splurge dinner. | E7: Day 4 dinner (book 2wks ahead)
A8: Aristocrat Restaurant (Roxas Blvd) | B8: Malate | C8: ₱300-500 | D8: Manila institution since 1936. Famous chicken BBQ + java rice + atchara. Heritage feel, often packed Sundays after Mass. | E8: Day 1 dinner post Baywalk
A9: Romulo Café | B9: QC original / Makati branch | C9: ₱500-900 | D9: Heritage Filipino — Tito Greg's adobo flakes, chicken relleno, dinuguan empanadas. Named after Carlos P. Romulo. Good for groups. | E9: Day 4 lunch alt
A10: Sentro 1771 | B10: Greenbelt 3 / Capitol Commons | C10: ₱500-800 | D10: Modern Filipino — corned-beef sinigang (iconic), bagnet, ensaladang mangga. Solid sit-down option. | E10: Day 5 final lunch
A11: Leslie's Restaurant Tagaytay | B11: Aguinaldo Hwy, Tagaytay | C11: ₱500-900 | D11: Classic bulalo (beef bone-marrow stew) with Taal Lake panorama. Tourist mainstay but worth it for the view + the broth. | E11: Day 3 Tagaytay bulalo lunch
A12: Wildflour Café + Bakery | B12: Salcedo / BGC / Podium | C12: ₱300-600 | D12: Upscale all-day café — eggs benedict, salted caramel ensaymada, fresh pastries. Reliable any day. | E12: Breakfast / brunch
A14: 💆 Spas
A15: Place | B15: Area | C15: Price (PHP) | D15: Notes | E15: When
A16: The Spa (Fort Bonifacio) | B16: BGC | C16: ₱1,200-3,200 | D16: Reliable mid-range chain — Swedish, hilot, hot stone. Couples rooms. Book ahead Sat/Sun. | E16: Day 4 evening
A17: Nuat Thai | B17: Multiple branches (Makati/BGC/QC) | C17: ₱400-700 | D17: Cheap reliable Thai massage chain. Walk-in possible. Foot reflex highly recommended after Intramuros walking day. | E17: Any evening / post Intramuros walk
A18: Devarana Spa (Dusit Thani) | B18: Makati (Ayala Center) | C18: ₱4,500-6,500 | D18: Luxury hotel spa, Thai-inspired rituals, signature Devarana 150min package. Best splurge. | E18: Splurge — 120-150min ritual
A19: Mandala Spa (Antipolo) | B19: Antipolo (~28km E) | C19: ₱3,000-5,000 | D19: Hidden hillside spa retreat. Pair with Pinto Art Museum for half-day off-radar wellness combo. | E19: Day 3 v2 — pair with Pinto
A21: 🍻 Nightlife
A22: Place | B22: Area | C22: Price (PHP) | D22: Notes | E22: When
A23: Z Hostel Rooftop Bar | B23: Poblacion, Makati | C23: ₱200-350 | D23: Open-air rooftop bar — sunset cocktails, Manila skyline view. Crowd builds 21:00 onward. | E23: Day 2 — start of crawl
A24: The Curator | B24: Legaspi Village, Makati | C24: ₱500-700 | D24: Speakeasy behind coffee shop. World's 50 Best Bars alum. Craft cocktails. Reservation recommended Fri/Sat. | E24: Day 4 nightcap (book ahead)
A25: Run Rabbit Run | B25: Poblacion, Makati | C25: ₱400-600 | D25: Speakeasy behind grocery façade. Cocktails + small plates. Hidden door experience. | E25: Day 2 — Poblacion crawl
A26: The Bank Bar | B26: RCBC Plaza, Makati | C26: ₱500-800 | D26: Concealed inside RCBC Plaza — enter via Ze Royal Filipino-Cuban restaurant. Classic cocktail focus. | E26: Day 4 alt nightcap
A27: Sky Deck Bayleaf | B27: Intramuros (Bayleaf Hotel) | C27: ₱400-700 | D27: Rooftop bar atop Bayleaf — Intramuros + Manila Bay views. Less crowded than Poblacion. | E27: Day 1 sunset alt

Sheet 9. Hidden Gems & Swaps
A1: 💎 Hidden Gems & Anti-Tourist Swaps
A2: All vetted as light-traffic vs the standard tourist circuit. Distance from Makati CBD (Ayala / Poblacion side).
A4: NATURE / SCENIC
A5: Place | B5: Distance | C5: Travel time | D5: Why it stays quiet | E5: Notes / When | F5: Tried?
A6: Pinto Art Museum (Antipolo) | B6: ~28 km E | C6: ~75 min | D6: Whitewashed art compound on hillside; intentional curation vs tour-bus crowds | E6: ₱250; pair with Antipolo Church + viewpoint | F6: ☐
A7: La Mesa Eco Park (QC) | B7: ~17 km NE | C7: ~50 min | D7: 33-hectare watershed forest, walking trails, picnic. Most tourists never go. | E7: ₱60; weekday best | F7: ☐
A8: Las Piñas Bamboo Organ | B8: ~20 km SW | C8: ~50 min | D8: 1816 bamboo pipe organ in St Joseph Parish — Nat'l Cultural Treasure | E8: ₱150; weekday morning | F8: ☐
A10: BEACHES / DAY TRIPS
A11: Place | B11: Distance | C11: Travel time | D11: Why it stays quiet | E11: Notes / When | F11: Tried?
A12: Anvaya Cove / Bataan | B12: ~120 km NW | C12: ~3 hr | D12: Day-pass beach club on Subic Bay; far quieter than Boracay-adjacent stuff | E12: Overnight stay easier | F12: ☐
A13: Caliraya Resort (Laguna) | B13: ~110 km SE | C13: ~2.5 hr | D13: Pine-forest reservoir, kayaks; cooler than Tagaytay | E13: Day-trip possible but tight | F13: ☐
A14: Corregidor (slow version) | B14: ~45 km W (ferry) | C14: ~90 min ferry | D14: Overnight Corregidor Inn = empty island sunset | E14: ₱6,500 overnight pkg via Sun Cruises | F14: ☐
A16: FOOD (local-only)
A17: Place | B17: Distance | C17: Travel time | D17: Why it stays quiet | E17: Notes / When | F17: Tried?
A18: Sincerity Restaurant | B18: Binondo ~8 km | C18: ~28 min | D18: Cantonese fried chicken + kiampong; locals' favorite, hidden alley | E18: Cash only; no English menu — point at neighbours | F18: ☐
A19: Toho Antigua Panciteria | B19: Binondo ~8 km | C19: ~28 min | D19: Manila's OLDEST restaurant (1888); pancit + lumpia | E19: Heritage feel; ₱300-500 | F19: ☐
A20: Café Adriatico (Malate) | B20: ~7 km W | C20: ~25 min | D20: 1979 LJC institution; bibingka + paella; quiet weekday | E20: ₱500-800 | F20: ☐
A21: Mañam Comfort Filipino | B21: Greenbelt 2 walk | C21: ~10 min | D21: Modern Filipino tapas; weekday lunch easy walk-in | E21: ₱400-700; try sinigang sa watermelon | F21: ☐
A22: Mercato Centrale (BGC weekend) | B22: BGC ~4 km | C22: ~18 min | D22: Fri-Sat 18:00-03:00 night food market; locals' weekly ritual | E22: ₱100-400; cash heavy | F22: ☐
A24: COFFEE (specialty)
A25: Place | B25: Distance | C25: Travel time | D25: Why it stays quiet | E25: Notes / When | F25: Tried?
A26: Yardstick Coffee | B26: Legaspi Village ~0.5 km | C26: ~5 min walk | D26: Manila's specialty third-wave pioneer; locals work from here | E26: ₱150-300 | F26: ☐
A27: EDSA Beverage Design Studio | B27: BGC ~4 km | C27: ~18 min | D27: Single-origin tasting flights; coffee + cocktails | E27: ₱200-500 | F27: ☐
A28: Tilde Handcrafted Café | B28: Cubao ~12 km | C28: ~35 min | D28: Cubao Expo arts district; quiet vinyl + coffee | E28: Pair with Cubao Expo art browse | F28: ☐
A30: CULTURE (low-traffic)
A31: Place | B31: Distance | C31: Travel time | D31: Why it stays quiet | E31: Notes / When | F31: Tried?
A32: Escolta Street + HUB:Make Lab | B32: ~8 km N | C32: ~28 min | D32: Heritage art district; First Saturday Block Party. Often missed. | E32: Free; Calvo Bldg, Regina Bldg | F32: ☐
A33: Manila Chinese Cemetery | B33: ~11 km N | C33: ~35 min | D33: Mausoleums w/ AC + mailboxes — surreal 'mini-city' | E33: Free; hire pedicab guide ₱500 | F33: ☐
A34: Bahay Tsinoy | B34: Intramuros ~8 km | C34: ~28 min | D34: Chinese-Filipino history museum; AC, rarely busy | E34: ₱200; 1.5hr | F34: ☐
A35: Cubao Expo | B35: ~12 km NE | C35: ~35 min | D35: Indie design + vinyl + vintage compound; locals' creative scene | E35: Free entry; weekday quieter | F35: ☐
A36: Marikina Shoe Museum | B36: ~22 km E | C36: ~55 min | D36: Imelda Marcos's 800 shoes + shoemaking history | E36: ₱100; eccentric niche | F36: ☐
A38: WELLNESS (off-radar)
A39: Place | B39: Distance | C39: Travel time | D39: Why it stays quiet | E39: Notes / When | F39: Tried?
A40: The Farm at San Benito (day-pass) | B40: ~100 km S (Batangas) | C40: ~2.5 hr | D40: Award-winning wellness retreat day-pass; vegan lunch + pool | E40: Splurge ~₱8,500; book ahead | F40: ☐
A41: Mandala Spa (Boracay quality, Antipolo) | B41: ~28 km E | C41: ~75 min | D41: Hidden hillside spa retreat; pair w/ Pinto | E41: ₱3,000-5,000 | F41: ☐
A42: Nuat Thai (Salcedo branch) | B42: walk | C42: 5 min | D42: Less busy than Greenbelt branch; weekday afternoon walk-in | E42: ₱500-700 | F42: ☐

Sheet 10. Activity Pricing
A1: 💵 Activity Pricing — Pick ONE Bundle Per Activity
A2: ⚠️ READ FIRST: For bundled activities PICK ONE PATH only — do NOT add rows. GROUP DAY TOURS bundle transport + ticket + lunch in ONE price.
A4: 🚌 TAGAYTAY DAY TRIP — PICK ONE BUNDLE
A5: Item | B5: Channel | C5: Local PHP | D5: SGD (≈) | E5: Includes | F5: ☐ | G5: Confirmed price
A6: PATH 1 — Klook GROUP DAY TOUR | B6: Klook shared van | C6: 2200 | D6: =C6/'12. Budget'!$B$3 | E6: ALL-IN: RT van + Picnic Grove + Sky Ranch entry + bulalo lunch + Sonya's. Group of 10-15. Cheapest path. | F6: ☐
A7: PATH 2 — Private Grab car RT | B7: Direct Grab/private booking | C7: 4500 | D7: =C7/'12. Budget'!$B$3 | E7: Private car + driver RT (8hr). Entries + lunch NOT incl. Most flexible. | F7: ☐
A8: PATH 3 — Self-drive rental | B8: Klook/Avis car rental | C8: 3500 | D8: =C8/'12. Budget'!$B$3 | E8: Self-drive small SUV 24hr + fuel + toll. NLEX-CAVITEX. Independence; need PH license. | F8: ☐
A9: PATH 4 — DIY by P2P bus | B9: DLTB / Genesis bus from Cubao or PITX | C9: 250 | D9: =C9/'12. Budget'!$B$3 | E9: BUS ONLY one-way. Cheap, slow. Add jeepney/tricycle at Tagaytay. For backpackers. | F9: ☐
A10: Optional: Sky Ranch ferris wheel | B10: on-site | C10: 250 | D10: =C10/'12. Budget'!$B$3 | E10: Single ride | F10: ☐
A11: Optional: People's Park in the Sky entry | B11: on-site | C11: 100 | D11: =C11/'12. Budget'!$B$3 | E11: Entry only | F11: ☐
A12: Optional: Taal Lake boat to volcano crater | B12: Talisay Lakeside Brgy | C12: 1800 | D12: =C12/'12. Budget'!$B$3 | E12: Bangka boat + island fee. Check PHIVOLCS volcano alert level FIRST. | F12: ☐
A14: 🏝️ CORREGIDOR DAY TRIP — PICK ONE BUNDLE
A15: Item | B15: Channel | C15: Local PHP | D15: SGD (≈) | E15: Includes | F15: ☐ | G15: Confirmed price
A16: PATH 1 — Sun Cruises full-day | B16: Sun Cruises (sole ferry operator) | C16: 2999 | D16: =C16/'12. Budget'!$B$3 | E16: RT ferry from ESPLANADE + tram tour + buffet lunch + guide. 06:30-15:30. Only practical path. | F16: ☐
A17: PATH 2 — Overnight Corregidor | B17: Sun Cruises + Corregidor Inn | C17: 6500 | D17: =C17/'12. Budget'!$B$3 | E17: Tour + Corregidor Inn 1 night + meals. Sunset + lights-of-Manila view. | F17: ☐
A18: Optional: Light & Sound Show (Malinta Tunnel) | B18: on-site | C18: 200 | D18: =C18/'12. Budget'!$B$3 | E18: Add-on, 30min | F18: ☐
A20: 🚶 INTRAMUROS — PICK ONE BUNDLE
A21: Item | B21: Channel | C21: Local PHP | D21: SGD (≈) | E21: Includes | F21: ☐ | G21: Confirmed price
A22: PATH 1 — Self-walk + entries | B22: DIY | C22: 350 | D22: =C22/'12. Budget'!$B$3 | E22: Fort Santiago ₱75 + San Agustin ₱200 + Casa Manila ₱75. Walk between. Cheapest. | F22: ☐
A23: PATH 2 — Bambike Eco-Tour | B23: Bambike Intramuros | C23: 1200 | D23: =C23/'12. Budget'!$B$3 | E23: Bamboo bike + guide + all entries 2.5hr. Most fun moderate-cost option. | F23: ☐
A24: PATH 3 — Kalesa carriage hire | B24: Plaza San Luis | C24: 800 | D24: =C24/'12. Budget'!$B$3 | E24: 1hr horse-drawn carriage tour. Tourist-y but classic. NEGOTIATE before boarding. | F24: ☐
A25: PATH 4 — Old Manila Walks Intramuros tour | B25: Old Manila Walks | C25: 1500 | D25: =C25/'12. Budget'!$B$3 | E25: 3hr guided walk + entries. Strong historian-led. | F25: ☐
A27: 🍜 BINONDO FOOD CRAWL — PICK ONE BUNDLE
A28: Item | B28: Channel | C28: Local PHP | D28: SGD (≈) | E28: Includes | F28: ☐ | G28: Confirmed price
A29: PATH 1 — Old Manila Walks Big Binondo Food Wok | B29: Old Manila Walks | C29: 1500 | D29: =C29/'12. Budget'!$B$3 | E29: 4hr guided + 6-8 food stops. Most comprehensive. | F29: ☐
A30: PATH 2 — Ivan ManDy independent | B30: @theoldmanilawalks | C30: 1800 | D30: =C30/'12. Budget'!$B$3 | E30: Premium small-group; books out fast. | F30: ☐
A31: PATH 3 — DIY self-guided | B31: Walk | C31: 700 | D31: =C31/'12. Budget'!$B$3 | E31: Hit Wai Ying + Eng Bee Tin + Lord Stow's + Sincerity + Polland. ~₱700 food. | F31: ☐
A33: 💆 SPA — PICK ONE
A34: Item | B34: Channel | C34: Local PHP | D34: SGD (≈) | E34: Includes | F34: ☐ | G34: Confirmed price
A35: PATH 1 — Nuat Thai 60min foot reflex | B35: Nuat Thai walk-in | C35: 500 | D35: =C35/'12. Budget'!$B$3 | E35: 60min foot. Cheap, reliable chain. | F35: ☐
A36: PATH 2 — The Spa BGC 90min Swedish | B36: The Spa BGC | C36: 2200 | D36: =C36/'12. Budget'!$B$3 | E36: 90min full body. Mid-range. | F36: ☐
A37: PATH 3 — Dusit Devarana Spa 150min ritual | B37: Dusit Thani Manila | C37: 6000 | D37: =C37/'12. Budget'!$B$3 | E37: Hotel luxury spa. Splurge. | F37: ☐

Sheet 11. Distance Matrix
A1: 🗺️ Distance & Travel-Time Reference Matrix
A4: From | B4: To | C4: Distance (km) | D4: Travel time (min) | E4: Typical fare
A5: NAIA Airport | B5: Makati CBD hotels | C5: 8.5 | D5: 35 | E5: 350
A6: Makati CBD | B6: Intramuros / Fort Santiago | C6: 7.5 | D6: 28 | E6: 280
A7: Makati CBD | B7: Rizal Park / National Museum | C7: 6.2 | D7: 25 | E7: 250
A8: Makati CBD | B8: Binondo Chinatown | C8: 8.2 | D8: 30 | E8: 320
A9: Makati CBD | B9: Quiapo Church | C9: 8 | D9: 28 | E9: 320
A10: Makati CBD | B10: Manila Baywalk (Roxas Blvd) | C10: 6.5 | D10: 22 | E10: 280
A11: Makati CBD | B11: BGC Bonifacio High Street | C11: 4 | D11: 18 | E11: 200
A12: Makati CBD | B12: Poblacion bars | C12: 0.5 | D12: 5 | E12: 100
A13: Makati CBD | B13: Tagaytay (Picnic Grove) | C13: 60 | D13: 105 | E13: 3500
A14: Makati CBD | B14: Corregidor Ferry Terminal (ESPLANADE) | C14: 7 | D14: 25 | E14: 300
A15: Makati CBD | B15: Pinto Art Museum Antipolo | C15: 28 | D15: 75 | E15: 850
A16: Makati CBD | B16: Manila Chinese Cemetery | C16: 11 | D16: 35 | E16: 400
... A18: Makati CBD | B18: SM MOA (Mall of Asia) | C18: 7.5 | D18: 25 | E18: 300
A19: Makati CBD (Ayala / Poblacion side) | B19: Intramuros (Walled City) | C19: 7.5 | D19: 25
A20: Makati CBD (Ayala / Poblacion side) | B20: Rizal Park (Luneta) | C20: 6 | D20: 22
A21: Makati CBD (Ayala / Poblacion side) | B21: National Museum Complex | C21: 6.2 | D21: 22
A22: Makati CBD (Ayala / Poblacion side) | B22: Binondo (Chinatown) | C22: 8.2 | D22: 28
A23: Makati CBD (Ayala / Poblacion side) | B23: Manila Cathedral | C23: 7.5 | D23: 25
A24: Makati CBD (Ayala / Poblacion side) | B24: San Agustin Church | C24: 7.5 | D24: 25
A25: Makati CBD (Ayala / Poblacion side) | B25: Ayala Museum | C25: 1.5 | D25: 8
A26: Makati CBD (Ayala / Poblacion side) | B26: Bonifacio Global City (BGC) | C26: 4 | D26: 18
A27: Makati CBD (Ayala / Poblacion side) | B27: Manila Baywalk + Sunset | C27: 6.5 | D27: 22
A28: Makati CBD (Ayala / Poblacion side) | B28: Tagaytay (Taal Volcano view) | C28: 60 | D28: 105
A29: Makati CBD (Ayala / Poblacion side) | B29: Corregidor Island | C29: 45 | D29: 90
A30: Makati CBD (Ayala / Poblacion side) | B30: Escolta Street | C30: 8 | D30: 28
... A32: Makati CBD (Ayala / Poblacion side) | B32: Pinto Art Museum (Antipolo) | C32: 28 | D32: 75
A34: 🚕 Transport Tips
A35: • Grab >> regular taxi. Predictable fare, no haggling, GCash payment. Surge during rain — wait 5min.
A36: • EDSA traffic worst Mon-Fri 16:30-20:00 and Sun 19:00-22:00 (return-to-city). Plan around.
A37: • Jeepney for adventure only — minimal English, ₱13-20 fixed. Don't try with luggage.
A38: • Metro Manila Skyway costs ₱65-200 toll — Grab driver may ask cash for toll; OK to add to fare.
A39: • NAIA inter-terminal shuttle is FREE — pink bus loops T1↔T2↔T3↔T4 every 15 min.
A40: • Tagaytay private car ₱3,500-4,500 RT; avoid Sat morning outbound traffic by leaving by 07:00.
A41: • P2P bus to Tagaytay (DLTB/Genesis) ₱250 from Cubao or PITX — slow but cheap.

Sheet 12. Budget
A1: 💰 Budget Estimate per Person
A3: Exchange rate (PHP per 1 SGD) | B3: 43 | C3: ← edit to update all SGD figures
A5: Category | B5: PHP (low) | C5: PHP (high) | D5: SGD (low) | E5: SGD (high)
A6: Food (5 days) | B6: 7500 | C6: 14000 | D6: =B6/$B$3 | E6: =C6/$B$3
A7: Transport — Grab + day trip | B7: 4500 | C7: 7000 | D7: =B7/$B$3 | E7: =C7/$B$3
A8: Activities + entries | B8: 3000 | C8: 5500 | D8: =B8/$B$3 | E8: =C8/$B$3
A9: Spas + wellness | B9: 1500 | C9: 5000 | D9: =B9/$B$3 | E9: =C9/$B$3
A10: Nightlife (optional) | B10: 0 | C10: 2500 | D10: =B10/$B$3 | E10: =C10/$B$3
A11: SIM / data | B11: 400 | C11: 800 | D11: =B11/$B$3 | E11: =C11/$B$3
A12: Pasalubong / souvenirs | B12: 1500 | C12: 4000 | D12: =B12/$B$3 | E12: =C12/$B$3
A13: Ground costs subtotal | B13: =SUM(B6:B12) | C13: =SUM(C6:C12) | D13: =B13/$B$3 | E13: =C13/$B$3
A15: Flight & hotel (direct SGD)
A16: Category | D16: SGD (low) | E16: SGD (high)
A17: Flights return | D17: 60 | E17: 180
A18: Hotel (4 nights) | D18: 140 | E18: 1200
A19: GRAND TOTAL (per person) | D19: =D13+D17+D18 | E19: =E13+E17+E18

Sheet 13. Practical Info
A1: 🧭 Practical Info
A3: Visa (PH passport) | B3: Domestic travel — none. Show valid government ID (PH passport, UMID, driver's license, PRC) for check-in.
A4: Passport/ID | B4: PH passport or any valid government-issued photo ID. Passport not required for domestic.
A5: Hotel booking proof | B5: Have on phone — sometimes asked at hotel check-in for walk-ins.
A6: Currency | B6: PHP only. USD/SGD not accepted outside hotels/large malls.
A7: Exchange rate | B7: ~43 PHP per 1 SGD (recheck XE.com; volatile 41-45)
A8: Best ATMs | B8: BPI, BDO, Metrobank. Fee ₱200-250/withdrawal. AVOID generic Euronet ATMs.
A9: Cards | B9: Visa/MC at hotels, malls, mid+ restaurants. AmEx limited. Cash for jeepney, market, Binondo, Quiapo.
A10: Cash bring | B10: ₱2-3k/day for street/market — Binondo/Quiapo cash-heavy.
A11: Tipping | B11: Service charge often auto-added 10%. If not, 5-10% sit-down. Spa ₱50-100. Grab — round up.
A12: SIM/eSIM | B12: Globe or Smart tourist SIM at NAIA arrival ₱500-1000 (5-10GB, 5-7 days). Or Klook/Airalo eSIM ~SGD 8-12.
A13: Power | B13: 220V/60Hz. Type A/B/C plugs (US 2-pin fits). SG/UK Type G NOT compatible — bring adaptor.
A14: Tap water | B14: NOT potable. Bottled only. Hotels usually supply 2 bottles/day.
... A22: Travel insurance | B22: Optional for domestic but advisable for typhoon-season trip (Standard Insurance, Pioneer, Malayan)

Sheet 14. Pre-Departure Checklist
A1: ✅ Pre-Departure Checklist
A3: Category | B3: Item | C3: Done?
A4: Documents | B4: Valid PH passport or government-issued photo ID (UMID/driver's license/PRC) | C4: ☐
A5: Documents | B5: Return flight ticket printed + on phone | C5: ☐
A6: Documents | B6: Hotel booking confirmation printed + on phone | C6: ☐
A7: Documents | B7: Travel insurance policy + emergency hotline (if purchased) | C7: ☐
A8: Documents | B8: Photo of ID stored in cloud + phone | C8: ☐
A9: Money | B9: PHP cash ₱5,000-10,000 obtained from BPI/BDO ATM at origin | C9: ☐
A10: Money | B10: GCash topped up (₱2,000+) for Grab + Foodpanda + small retailers | C10: ☐
A11: Money | B11: Credit card limit increased for trip; notify bank if first-time Manila use | C11: ☐
A12: Tech | B12: Globe/Smart SIM or eSIM plan decided (buy at NAIA arrival counter) | C12: ☐
A13: Tech | B13: Universal travel adapter packed (if non-PH device with Type G plug) | C13: ☐
A14: Tech | B14: Power bank ≤100Wh (carry-on only on domestic flights) | C14: ☐
... A35: Pre-flight | B35: Screenshot all vouchers + boarding passes offline | C35: ☐
